Workbook

Sheet Income Statement
A1: UBER | H1: LYFT
A2: Breakdown | B2: TTM | C2: 46022 | D2: 45657 | E2: 45291 | F2: 44926 | H2: Breakdown | I2: 44926 | J2: 45291 | K2: 45657 | L2: 46022 | M2: TTM
A3: Total Revenue | B3: 53687000 | C3: 52017000 | D3: 43978000 | E3: 37281000 | F3: 31877000 | H3: Total Revenue | I3: 4095135 | J3: 4403589 | K3: 5786016 | L3: 6316261 | M3: 6516578
A4: Operating Revenue | B4: 53687000 | C4: 52017000 | D4: 43978000 | E4: 37281000 | F4: 31877000 | H4: Operating Revenue | I4: 4095135 | J4: 4403589 | K4: 5786016 | L4: 6316261 | M4: 6516578
A5: Cost of Revenue | B5: 31659000 | C5: 31338000 | D5: 26651000 | E5: 22457000 | F5: 19659000 | H5: Cost of Revenue | I5: 2435736 | J5: 2543954 | K5: 3337714 | L5: 3697653 | M5: 3698923
A6: Gross Profit | B6: 22028000 | C6: 20679000 | D6: 17327000 | E6: 14824000 | F6: 12218000 | H6: Gross Profit | I6: 1659399 | J6: 1859635 | K6: 2448302 | L6: 2618608 | M6: 2817655
A7: Operating Expense | B7: 15768000 | C7: 15114000 | D7: 14528000 | E7: 13714000 | F7: 14050000 | H7: Operating Expense | I7: 3118315 | J7: 2335239 | K7: 2567214 | L7: 2806982 | M7: 2982514
A8: Selling General and Administrative | B8: 8549000 | C8: 8139000 | D8: 7976000 | E8: 7038000 | F8: 7892000 | H8: Selling General and Administrative | I8: 1817692 | J8: 1352084 | K8: 1726320 | L8: 1877231 | M8: 2023086
A9: General & Administrative Expense | B9: 3382000 | C9: 3241000 | D9: 3639000 | E9: 2682000 | F9: 3136000 | H9: General & Administrative Expense | I9: 1286180 | J9: 871080 | K9: 937348 | L9: 1002130 | M9: 1057066
A10: Other G and A | B10: 3382000 | C10: 3241000 | D10: 3639000 | E10: 2682000 | F10: 3136000 | H10: Other G and A | I10: 1286180 | J10: 871080 | K10: 937348 | L10: 1002130 | M10: 1057066
A11: Selling & Marketing Expense | B11: 5167000 | C11: 4898000 | D11: 4337000 | E11: 4356000 | F11: 4756000 | H11: Selling & Marketing Expense | I11: 531512 | J11: 481004 | K11: 788972 | L11: 875101 | M11: 966020
A12: Research & Development | B12: 3538000 | C12: 3402000 | D12: 3109000 | E12: 3164000 | F12: 2798000 | H12: Research & Development | I12: 856777 | J12: 555916 | K12: 397073 | L12: 451419 | M12: 463076
A13: Depreciation Amortization Depletion | B13: 732000 | C13: 719000 | D13: 711000 | E13: 823000 | F13: 947000 | H13: Other Operating Expenses | I13: 443846 | J13: 427239 | K13: 443821 | L13: 478332 | M13: 496352
A14: Depreciation & amortization | B14: 732000 | C14: 719000 | D14: 711000 | E14: 823000 | F14: 947000 | H14: Operating Income | I14: -1458916 | J14: -475604 | K14: -118912 | L14: -188374 | M14: -164859
... A52: Net Income from Continuing Operation Net Minority Interest | B52: 8540000 | C52: 10053000 | D52: 9856000 | E52: 1887000 | F52: -9141000 | H52: Tax Effect of Unusual Items | I52: -29481.48 | J52: 0 | K52: 0 | L52: 0 | M52: 0
A53: Total Unusual Items Excluding Goodwill | B53: -1604000 | C53: -8000 | D53: 1205000 | E53: 1558000 | F53: -7169000
A54: Total Unusual Items | B54: -1604000 | C54: -8000 | D54: 1205000 | E54: 1558000 | F54: -7169000
A55: Normalized EBITDA | B55: 7718000 | C55: 6995000 | D55: 4180000 | E55: 2219000 | F55: -745000
A56: Tax Rate for Calcs | B56: 0 | C56: 0 | D56: 0 | E56: 0 | F56: 0
A57: Tax Effect of Unusual Items | B57: -641600 | C57: -1680 | D57: 253050 | E57: 143336 | F57: -136211

Sheet Balance Sheet
A1: UBER | G1: LYFT
A2: Breakdown | B2: 46022 | C2: 45657 | D2: 45291 | E2: 44926 | G2: Breakdown | H2: 44926 | I2: 45291 | J2: 45657 | K2: 46022
A3: Total Assets | B3: 61802000 | C3: 51244000 | D3: 38699000 | E3: 32109000 | G3: Total Assets | H3: 4556431 | I3: 4564467 | J3: 5435069 | K3: 9030053
A4: Current Assets | B4: 13993000 | C4: 12245000 | D4: 11297000 | E4: 9249000 | G4: Current Assets | H4: 2582859 | I4: 2577419 | J4: 2950533 | K4: 2919515
A5: Cash, Cash Equivalents & Short Term Investments | B5: 7633000 | C5: 6977000 | D5: 5407000 | E5: 4311000 | G5: Cash, Cash Equivalents & Short Term Investments | H5: 1796792 | I5: 1685184 | J5: 1984443 | K5: 1837181
A6: Cash And Cash Equivalents | B6: 7105000 | C6: 5893000 | D6: 4680000 | E6: 4208000 | G6: Cash And Cash Equivalents | H6: 281090 | I6: 558636 | J6: 759319 | K6: 1132009
A7: Other Short Term Investments | B7: 528000 | C7: 1084000 | D7: 727000 | E7: 103000 | G7: Other Short Term Investments | H7: 1515702 | I7: 1126548 | J7: 1225124 | K7: 705172
A8: Receivables | B8: 3827000 | C8: 3333000 | D8: 4121000 | E8: 3489000 | G8: Other Current Assets | H8: 786067 | I8: 892235 | J8: 966090 | K8: 1082334
A9: Accounts receivable | B9: 3827000 | C9: 3333000 | D9: 3404000 | E9: 2779000 | G9: Total non-current assets | H9: 1973572 | I9: 1987048 | J9: 2484536 | K9: 6110538
A10: Gross Accounts Receivable | B10: 3918000 | C10: 3428000 | D10: 3495000 | E10: 2859000 | G10: Net PPE | H10: 448615 | I10: 564046 | J10: 593261 | K10: 584109
A11: Allowance For Doubtful Accounts Receivable | B11: -91000 | C11: -95000 | D11: -91000 | E11: -80000 | G11: Gross PPE | H11: 672551 | I11: 811241 | J11: 855082 | K11: 950908
A12: Other Receivables | B12: 0 | C12: 482000 | D12: 717000 | E12: 710000 | G12: Properties | H12: 0 | I12: 0 | J12: 0 | K12: 0
A13: Prepaid Assets | B13: 408000 | C13: 415000 | D13: 400000 | E13: 310000 | G13: Machinery Furniture Equipment | H13: 364594 | I13: 482618 | J13: 494503 | K13: 555399
... A65: Common Stock | B65: 0 | C65: 0 | D65: 0 | E65: 0 | G65: Treasury Shares Number | H65: 0 | I65: 0 | J65: 0 | K65: 0
A66: Additional Paid in Capital | B66: 38101000 | C66: 42801000 | D66: 42264000 | E66: 40550000
A67: Retained Earnings | B67: -10628000 | C67: -20726000 | D67: -30594000 | E67: -32767000
A68: Gains Losses Not Affecting Retained Earnings | B68: -432000 | C68: -517000 | D68: -421000 | E68: -443000
A69: Other Equity Adjustments | B69: -432000 | C69: -517000 | D69: -421000 | E69: -443000
A70: Minority Interest | B70: 1042000 | C70: 918000 | D70: 1433000 | E70: 1164000
A71: Total Capitalization | B71: 37562000 | C71: 29905000 | D71: 20708000 | E71: 16605000
A72: Common Stock Equity | B72: 27041000 | C72: 21558000 | D72: 11249000 | E72: 7340000
A73: Capital Lease Obligations | B73: 1559000 | C73: 1629000 | D73: 1740000 | E73: 1874000
A74: Net Tangible Assets | B74: 17062000 | C74: 12367000 | D74: 1673000 | E74: -2797000
A75: Working Capital | B75: 1673000 | C75: 769000 | D75: 1843000 | E75: 396000
A76: Invested Capital | B76: 37562000 | C76: 31055000 | D76: 20733000 | E76: 16605000
A77: Tangible Book Value | B77: 17062000 | C77: 12367000 | D77: 1673000 | E77: -2797000
... A81: Ordinary Shares Number | B81: 2067905 | C81: 2107953 | D81: 2071144 | E81: 2005486

Sheet Cash Flow
A1: UBER | H1: LYFT
A2: Breakdown | B2: TTM | C2: 46022 | D2: 45657 | E2: 45291 | F2: 44926 | H2: Breakdown | I2: 44926 | J2: 45291 | K2: 45657 | L2: 46022 | M2: TTM
A3: Operating Cash Flow | B3: 10126000 | C3: 10099000 | D3: 7137000 | E3: 3585000 | F3: 642000 | H3: Operating Cash Flow | I3: -237285 | J3: -98244 | K3: 849737 | L3: 1168438 | M3: 1188883
A4: Cash Flow from Continuing Operating Activities | B4: 10126000 | C4: 10099000 | D4: 7137000 | E4: 3585000 | F4: 642000 | H4: Cash Flow from Continuing Operating Activities | I4: -237285 | J4: -98244 | K4: 849737 | L4: 1168438 | M4: 1188883
A5: Net Income from Continuing Operations | B5: 8601000 | C5: 10093000 | D5: 9845000 | E5: 2156000 | F5: -9138000 | H5: Net Income from Continuing Operations | I5: -1584511 | J5: -340320 | K5: 22784 | L5: 2844008 | M5: 2855691
A6: Operating Gains Losses | B6: -64000 | C6: -120000 | D6: 308000 | E6: 138000 | F6: -216000 | H6: Operating Gains Losses | I6: -60655 | J6: -11278 | K6: -21779 | L6: 7569 | M6: 11156
A7: Gain Loss On Sale of Business | B7: 0 | C7: 0 | D7: 0 | E7: -204000 | F7: -14000 | H7: Gain Loss On Sale of Business | I7: 0 | J7: 0 | K7: -29610 | L7: 0 | M7: 0
A8: Net Foreign Currency Exchange Gain Loss | B8: -64000 | C8: -120000 | D8: 308000 | E8: 138000 | F8: 96000 | H8: Depreciation Amortization Depletion | I8: 154798 | J8: 116513 | K8: 148892 | L8: 135227 | M8: 138280
A9: Gain Loss On Investment Securities | B9: 0 | C9: 0 | D9: 0 | E9: 74000 | F9: -191000 | H9: Depreciation & amortization | I9: 154798 | J9: 116513 | K9: 148892 | L9: 135227 | M9: 138280
A10: Earnings Losses from Equity Investments | B10: 0 | C10: 0 | D10: 38000 | E10: -48000 | F10: -107000 | H10: Deferred Tax | I10: 0 | J10: -2385 | K10: -1876 | L10: -2895119 | M10: -2893370
A11: Depreciation Amortization Depletion | B11: 760000 | C11: 747000 | D11: 737000 | E11: 823000 | F11: 947000 | H11: Deferred Income Tax | I11: 0 | J11: -2385 | K11: -1876 | L11: -2895119 | M11: -2893370
A12: Depreciation & amortization | B12: 760000 | C12: 747000 | D12: 737000 | E12: 823000 | F12: 947000 | H12: Amortization of Securities | I12: -20290 | J12: -68008 | K12: -89141 | L12: -68929 | M12: -60681
A13: Deferred Tax | B13: -4261000 | C13: -4779000 | D13: -6027000 | E13: 26000 | F13: -441000 | H13: Asset Impairment Charge | I13: 135714 | J13: 0 | K13: 0 | L13: 0 | M13: 0
A14: Deferred Income Tax | B14: -4261000 | C14: -4779000 | D14: -6027000 | E14: 26000 | F14: -441000 | H14: Stock based compensation | I14: 750767 | J14: 484533 | K14: 330921 | L14: 322268 | M14: 315988
... A60: Issuance of Capital Stock | B60: 0 | C60: 0 | D60: 0 | E60: 0 | F60: 255000 | H60: Free Cash Flow | I60: -352255 | J60: -248063 | K60: 766267 | L60: 1115616 | M60: 1122138
A61: Issuance of Debt | B61: 5099000 | C61: 3359000 | D61: 3972000 | E61: 2824000 | F61: 0
A62: Repayment of Debt | B62: -2500000 | C62: -2507000 | D62: -4158000 | E62: -2846000 | F62: -264000
A63: Repurchase of Capital Stock | B63: -7749000 | C63: -6523000 | D63: -1252000 | E63: 0 | F63: 0
A64: Free Cash Flow | B64: 9799000 | C64: 9763000 | D64: 6895000 | E64: 3362000 | F64: 390000

Sheet Cover
A1: Uber × Lyft Acquisition Valuation Analysis
A6: Prepared By | C6: Rashmi Leema [Financial Analyst/Data Analyst]
A9: Tools Used | C9: • Financial Modeling • DCF • Valuation • Scenario Analysis • Forecasting
A12: Project Objective | C12: Evaluate the strategic acquisition of Lyft by Uber using DCF valuation, synergy analysis, sensitivity analysis, and financial forecasting.

Sheet COVER2
A2: Date
A4: Prepared by | C4: Rashmi Leema
A7: Project Name | C7: Uber × Lyft Acquisition Valuation Analysis
A9: Project Description
A11: Skills Used

Sheet EXECUTIVE DASHBOARD
A1: 1 EXECUTIVE DASHBOARD | D1: ENTERPRISE VALUE | G1: INTRINSIC VALUE | J1: TOTAL SYNERGY VALUE | M1: REVENUE CAGR (2025-2030) | P1: EBITDA MARGIN (2030) | S1: RECOMMENDATION
D2: ='DCF & SENSITIVITY ANALYSIS'!D7 -> 18219244 | G2: ='DCF & SENSITIVITY ANALYSIS'!D31 -> 48.274824 | J2: =SYNERGIES!X8 -> 2146700.1 | M2: =('FORECAST MODEL & FCF BUILD UP'!N6/'FORECAST MODEL & FCF BUILD UP'!D6)^(1/5)-1 -> 0.079976851 | P2: ='FORECAST MODEL & FCF BUILD UP'!N14 -> 0.085 | S2: CONDITIONAL BUY
A3: 2 TRANSACTION OVERVIEW
A5: 3 HISTORIC FINANCIALS
D6: USD thousand | G6: USD per share | J6: USD thousand | M6: Lyft Inc; | P6: Lyft Inc; | S6: Value Accretive
A7: 4 ASSUMPTIONS
P8: VALUATION SUMMARY
A9: 5 FORECAST MODEL & FCF BUILD UP
P10: Enterprise Value (USD thousand) | T10: ='DCF & SENSITIVITY ANALYSIS'!C26 -> 18219244
A11: 6 DCF & SENSITIVITY ANALYSIS
P12: + Net Debt (USD thousand)' | T12: ='DCF & SENSITIVITY ANALYSIS'!C28 -> 0
A13: 7 SYNERGIES ANALYSIS
P14: - Cash (USD thousand) | T14: ='DCF & SENSITIVITY ANALYSIS'!C27 -> 1132009
A15: 8 RECOMMENDATION
P16: Shares Outstanding (As of 31/12/2025) | T16: ='DCF & SENSITIVITY ANALYSIS'!D23 -> 400856000
A17: Transaction Summary
P18: Implied Share Price (USD) | T18: ='DCF & SENSITIVITY ANALYSIS'!D31 -> 48.274824
A20: Acquirer | P20: Current Share Price (USD) | T20: ='DCF & SENSITIVITY ANALYSIS'!D40 -> 16.534593
A21: Uber Technologies Inc.
P22: Upside / (Downside) | T22: =(T18-T20) -> 31.74023
A23: Target
A24: Lyft Inc.
P25: WACC | Q25: Terminal Growth Rate
A26: Transaction Type | Q26: 0.015 | R26: 0.02 | S26: 0.025 | T26: 0.025 | U26: 0.035
A27: Strategic Acquisition | P27: 0.075 | Q27: 22941049 | R27: 23932096 | S27: 25121352 | T27: 25121352 | U27: 28391806
A29: Industry | P29: 0.08 | Q29: 21725716 | R29: 22548873 | S29: 23521694 | T29: 23521694 | U29: 26115883
A30: Ride Hailing / Mobility
P31: 0.085 | Q31: 20665279 | R31: 21357925 | S31: 22166013 | T31: 22166013 | U31: 24267040
A32: Currency
A33: USD | P33: 0.09 | Q33: 19729461 | R33: 20318815 | S33: 20998840 | T33: 20998840 | U33: 22729811
A35: Analysis Date | P35: 0.095 | Q35: 18895528 | R35: 19401859 | S35: 19980522 | T35: 19980522 | U35: 21427181
A36: 46023
B38: SUMMARY FINANCIALS (USD thousand)
D39: 2022A | F39: 2023A | H39: 2024A | J39: 2025A | L39: 2026E | N39: 2027E | P39: 2028E | R39: 2029E | T39: 2030E
B40: Revenue | D40: 4095135 | F40: 4403589 | H40: 5786016 | J40: 6316261 | L40: 6884724.5 | N40: 7469926.1 | P40: 8067520.2 | R40: 8672584.2 | T40: 9279665.1
B41: EBIT | D41: -1458916 | F41: -475604 | H41: -118912 | J41: -188374 | L41: 378659.85 | N41: 463135.42 | P41: 564726.41 | R41: 676461.57 | T41: 788771.53
B42: Tax | D42: 5872 | F42: 8616 | H42: 2566 | J42: -2897255 | L42: 56798.977 | N42: 78733.021 | P42: 107298.02 | R42: 142056.93 | T42: 173529.74
B43: NOPAT | D43: =D41-D42 -> -1464788 | F43: =F41-F42 -> -484220 | H43: =H41-H42 -> -121478 | J43: =J41-J42 -> 2708881 | L43: =L41-L42 -> 321860.87 | N43: 384402.4 | P43: 457428.39 | R43: 534404.64 | T43: 615241.79
B44: + D&A | D44: 154798 | F44: 116513 | H44: 148892 | J44: 135227 | L44: 136317.54 | N44: 144169.57 | P44: 150862.63 | R44: 158708.29 | T44: 167033.97
B45: - CapEx | D45: -114970 | F45: -149819 | H45: -83470 | J45: -52822 | L45: 68847.245 | N45: 82169.187 | P45: 96810.242 | R45: 112743.59 | T45: 139194.98
...

Sheet data
A2: Dollars in thousands) | B2: 2022A | C2: 2023A | D2: 2024A | E2: 2025A | F2: 2026E | G2: 2027E | H2: 2028E | I2: 2029E | J2: 2030E
A3: Total Revenue | B3: 4095135 | C3: 4403589 | D3: 5786016 | E3: 6316261 | F3: 6884724.5 | G3: 7469926.1 | H3: 8067520.2 | I3: 8672584.2 | J3: 9279665.1
A4: EBITDA | B4: -1404106 | C4: -188968 | D4: 203163 | E4: 102735 | F4: 514977.39 | G4: 607304.99 | H4: 715589.04 | I4: 835169.86 | J4: 955805.5
A5: EBITDA Margin | B5: -0.34287172 | C5: -0.04291227 | D5: 0.035112762 | E5: 0.016265161 | F5: 0.0748 | G5: 0.0813 | H5: 0.0887 | I5: 0.0963 | J5: 0.103
A6: FCF | B6: -352255 | C6: -248063 | D6: 766267 | E6: 1115616 | F6: 1284345.4 | G6: 1380143.5 | H6: 1479583.2 | I6: 1577716.5 | J6: 1663843.9

Sheet TRANSACTION OVERVIEW
A1: Transaction Overview
A3: STRATEGIC RATIONALE
A8: MARKET CONSOLIDATION | F8: COST SYNERGIES | K8: INCREASED PRICING POWER | P8: TECHNOLOGY INTEGRATION
A10: A potential acquisition of Uber Technologies by Lyft would significantly strengthen Uber’s dominance in the North American ride hailing market by reducing direct competition and increasing market share. | F10: Estimated cost savings may arise from reduced overlappping operational expenses, workforce optimization, consolidated marketing spend, and technology integration. | K10: The acquisition would provide access to Lyft’s existing customer network, allowing Uber to increase ride volume, cross-sell services, and improve customer retention across mobility offerings. | P10: The acquisition could enhance Uber's route optimization, pricing algorithms, customer analytics, and autonomous driving research through combined datasets and technological capabilities.
A17: KEY RISKS
A20: Risk Factor | G20: Description | R20: Impact
B22: Regulatory Approval | G22: High risk of antitrust scrutiny and regulatory approval delays.
B24: Antitrust Concerns | G24: Market concentration may face challenges from regulators globally.
B26: Integration Complexity | G26: Integration technology, operations, and corporate cultures may be challenging.
B28: Revenue Synergies | G28: Uncertainty in achieving projected revenue synergies.
B30: Cost Synergies | G30: High visibilty and strong potential for realizing cost savings.

Sheet HISTORICAL FINANCIALS
A1: HISTORICAL FINANCIALS
A3: Dollars in thousands) | D3: FISCAL 2025 | F3: FISCAL 2024 | H3: % CHANGE | J3: FISCAL 2023 | L3: % CHANGE | N3: FISCAL 2022 | P3: % CHANGE
H4: % CHANGE | L4: % CHANGE | P4: % CHANGE
A5: LYFT, Inc. :
A6: Total Revenue | D6: 6316261 | F6: 5786016 | H6: =(D6-F6)/F6 -> 0.091642505 | J6: 4403589 | L6: =(F6-J6)/J6 -> 0.31393189 | N6: 4095135 | P6: =(J6-N6)/N6 -> 0.075322059
A7: Cost of Revenue | D7: 3697653 | F7: 3337714 | H7: =(D7-F7)/F7 -> 0.10783998 | J7: 2543954 | L7: =(F7-J7)/J7 -> 0.31201822 | N7: 2435736 | P7: =(J7-N7)/N7 -> 0.044429281
A8: Cost Ratio | D8: =D7/D6 -> 0.58541802 | F8: =F7/F6 -> 0.57685876 | J8: =J7/J6 -> 0.57770014 | N8: =N7/N6 -> 0.59478772
A9: Gross Profit | D9: =D6-D7 -> 2618608 | F9: =F6-F7 -> 2448302 | J9: =J6-J7 -> 1859635 | N9: =N6-N7 -> 1659399
A10: Gross Margin | D10: =D9/D6 -> 0.41458198 | E10: =D9/D6 -> 0.41458198 | F10: =F9/F6 -> 0.42314124 | G10: =F9/F6 -> 0.42314124 | J10: =J9/J6 -> 0.42229986 | K10: =J9/J6 -> 0.42229986 | N10: =N9/N6 -> 0.40521228 | O10: =N9/N6 -> 0.40521228
A11: Operating Expense | D11: 2806982 | F11: 2567214 | J11: 2335239 | N11: 3118315
A12: OpEx % Revenue | D12: =D11/D6 -> 0.44440564 | F12: =F11/F6 -> 0.44369286 | J12: =J11/J6 -> 0.53030358 | N12: =N11/N6 -> 0.76146818
A13: EBITDA | D13: 102735 | E13: 102735 | F13: 203163 | G13: 203163 | J13: -188968 | K13: -188968 | N13: -1404106 | O13: -1404106
A14: EBITDA Margin | D14: =D13/D6 -> 0.016265161 | F14: =F13/F6 -> 0.035112762 | J14: =J13/J6 -> -0.04291227 | N14: =N13/N6 -> -0.34287172
A15: Operating Income (EBIT) | D15: -188374 | F15: -118912 | J15: -475604 | N15: -1458916
A16: EBIT Margin | D16: =D15/D6 -> -0.029823657 | F16: =F15/F6 -> -0.02055162 | J16: =J15/J6 -> -0.10800372 | N16: =N15/N6 -> -0.3562559
A17: Operating Cash Flow | D17: 1168438 | F17: 849737 | J17: -98244 | N17: -237285
A18: D&A | D18: 135227 | F18: 148892 | J18: 116513 | N18: 154798
A19: D&A % Revenue | D19: =D18/D6 -> 0.021409343 | F19: =F18/F6 -> 0.025733078 | J19: =J18/J6 -> 0.026458645 | N19: =N18/N6 -> 0.037800463
A20: CapEx | D20: -52822 | F20: -83470 | J20: -149819 | N20: -114970
A21: CapEx % Revenue | D21: =D20/D6 -> -0.008362859 | F21: =F20/F6 -> -0.014426161 | J21: =J20/J6 -> -0.034022022 | N21: =N20/N6 -> -0.028074777
A22: Free Cash Flow | D22: 1115616 | F22: 766267 | J22: -248063 | N22: -352255
A23: FCF Margin | D23: =D22/D6 -> 0.17662601 | F23: =F22/F6 -> 0.1324343 | J23: =J22/J6 -> -0.056332006 | N23: =N22/N6 -> -0.086017921
A24: Cash | D24: 1132009 | F24: 759319 | J24: 558636 | N24: 281090
A25: Net Debt | D25: 0 | F25: 235728 | J25: 306524 | N25: 558404
A26: Net Income | D26: 2844008 | F26: 22784 | J26: -340320 | N26: -1584511
A27: Net Margin | D27: =D26/D6 -> 0.45026765 | F27: =F26/F6 -> 0.00393777 | J27: =J26/J6 -> -0.077282417 | N27: =N26/N6 -> -0.38692522
A29: Tax Provision | D29: -2897255 | E29: -2897255 | F29: 2566 | G29: 2566 | J29: 8616 | K29: 8616 | N29: 5872 | O29: 5872
A30: Pretax Income | D30: -53247 | E30: -53247 | F30: 25350 | G30: 25350 | J30: -331704 | K30: -331704 | N30: -1578639 | O30: -1578639
A32: Current Assets | D32: 2919515 | F32: 2950533 | J32: 2577419 | N32: 2582859
A33: Current Liabilities | D33: 4525821 | F33: 3880742 | J33: 2961561 | N33: 3132563
A35: Net Working Capital (NWC) | D35: =D32-D33 -> -1606306 | F35: =F32-F33 -> -930209 | J35: =J32-J33 -> -384142 | N35: =N32-N33 -> -549704
A36: Change in NWC | D36: =D35-F35 -> -676097 | F36: =F35-J35 -> -546067 | J36: =J35-N35 -> 165562
A37: NWC % Revenue | D37: =D36/D6 -> -0.1070407 | F37: =F36/F6 -> -0.094377029 | J37: =J36/J6 -> 0.03759706
A39: Current Ratio | D39: =D32/D33 -> 0.64507964 | F39: =F32/F33 -> 0.76030125 | J39: =J32/J33 -> 0.8702907 | N39: =N32/N33 -> 0.82451941
A40: Cash Ratio | D40: =D24/D33 -> 0.25012235 | F40: =F24/F33 -> 0.19566336 | J40: =J24/J33 -> 0.1886289 | N40: =N24/N33 -> 0.089731635

Sheet Lyft Analysis
A1: 1 | B1: Total Revenue
B3: Breakdown | C3: Total Revenue | D3: % Diff
B4: 46022 | C4: 6316261
B5: 45657 | C5: 5786016 | D5: =(C4-C5)/C5 -> 0.091642505 | E5: Market saturation / Competition
B6: 45291 | C6: 4403589 | D6: =(C5-C6)/C6 -> 0.31393189 | E6: A strong pandemic recovery growth
B7: 44926 | C7: 4095135 | D7: =(C6-C7)/C7 -> 0.075322059
A9: 2 | B9: Margins
A11: 2.1 | B11: Gross Margin
B13: Breakdown | C13: Total Revenue | D13: Gross Profit (Total Revenue - Total Cost) | E13: Gross Margin
B14: 46022 | C14: 6316261 | D14: 2618608 | E14: =D14/C14 -> 0.41458198 | F14: Relatively stable gross margins above 40%
B15: 45657 | C15: 5786016 | D15: 2448302 | E15: =D15/C15 -> 0.42314124 | F15: Core operations are covererd
B16: 45291 | C16: 4403589 | D16: 1859635 | E16: =D16/C16 -> 0.42229986
B17: 44926 | C17: 4095135 | D17: 1659399 | E17: =D17/C17 -> 0.40521228
A19: 2.2 | B19: Operating Margin
B21: Breakdown | C21: Total Revenue | D21: Operating Income (Gross Profit - Operating Expenses) | E21: Operating Margin
B22: 46022 | C22: 6316261 | D22: -188374 | E22: =D22/C22 -> -0.029823657
B23: 45657 | C23: 5786016 | D23: -118912 | E23: =D23/C23 -> -0.02055162 | F23: Operating leverage has improved
B24: 45291 | C24: 4403589 | D24: -475604 | E24: =D24/C24 -> -0.10800372
B25: 44926 | C25: 4095135 | D25: -1458916 | E25: =D25/C25 -> -0.3562559
A27: 2.3 | B27: EBITDA Margin
B29: Breakdown | C29: Total Revenue | D29: EBITDA
B30: 46022 | C30: 6316261 | D30: 102735
B31: 45657 | C31: 5786016 | D31: 203163
B32: 45291 | C32: 4403589 | D32: -188968
B33: 44926 | C33: 4095135 | D33: -1404106
A35: 3 | B35: Opearting Losses
B37: Breakdown | C37: Operating Income (Gross Profit - Operating Expenses)
B38: 46022 | C38: -188374 | D38: losses became MUCH smaller
B39: 45657 | C39: -118912 | D39: still not consistently profitable
B40: 45291 | C40: -475604
B41: 44926 | C41: -1458916
A43: 4 | B43: Cash Burn
A45: 4.1 | B45: Operating Cash Burn
B47: Breakdown | C47: Operating Cash Flow
B48: 46022 | C48: 1168438 | D48: generating cash
B49: 45657 | C49: 849737
B50: 45291 | C50: -98244
B51: 44926 | C51: -237285 | D51: burning cash
A53: 4.2 | B53: Free Cash Flow (FCF)
B55: Breakdown | C55: Operating Cash Flow | D55: Purchase of PPE | E55: FCF (Operating CF - Purchase of PPE)
...

Sheet ASSUMPTIONS
A1: ASSUMPTIONS
A3: Metric | D3: 2026E | F3: 2027E | H3: 2028E | J3: 2029E | L3: 2030E
F4: 2027E | H4: 2028E | J4: 2029E | L4: 2030E
A5: Revenue Growth | B5: 0.09 | C5: 0.085 | D5: 0.09 | F5: 0.085 | H5: 0.08 | J5: 0.075 | L5: 0.07
A7: Cost % Revenue | B7: 0.59 | C7: 0.588 | D7: 0.59 | F7: 0.588 | H7: 0.585 | J7: 0.582 | L7: 0.58
A9: OpEx % Revenue | B9: 0.355 | C9: 0.35 | D9: 0.355 | F9: 0.35 | H9: 0.345 | J9: 0.34 | L9: 0.335
A11: D&A % Revenue | B11: 0.0198 | C11: 0.0193 | D11: 0.0198 | F11: 0.0193 | H11: 0.0187 | J11: 0.0183 | L11: 0.018
A13: WACC | B13: 0.09 | C13: 0.09 | D13: 0.09 | F13: 0.09 | H13: 0.09 | J13: 0.09 | L13: 0.09
A15: Terminal Growth Rate | B15: 0.02 | C15: 0.02 | D15: 0.02 | F15: 0.02 | H15: 0.02 | J15: 0.02 | L15: 0.02
A17: Tax Rate | B17: 0.15 | C17: 0.17 | D17: 0.15 | F17: 0.17 | H17: 0.19 | J17: 0.21 | L17: 0.22
A19: CapEx % Revenue | B19: 0.01 | C19: 0.011 | D19: 0.01 | F19: 0.011 | H19: 0.012 | J19: 0.013 | L19: 0.015
A21: Change in NWC % Revenue | B21: -0.13 | C21: -0.125 | D21: -0.13 | F21: -0.125 | H21: -0.12 | J21: -0.115 | L21: -0.11

Sheet FORECAST MODEL & FCF BUILD UP
A1: FORECAST MODEL & FCF BUILD UP
A3: Dollars in thousands) | D3: FISCAL 2025 | F3: FISCAL 2026 | H3: FISCAL 2027 | J3: FISCAL 2028 | L3: FISCAL 2029 | N3: FISCAL 2030
F4: FISCAL 2026 | J4: FISCAL 2026 | N4: FISCAL 2026
A5: LYFT, Inc. :
A6: Total Revenue | D6: 6316261 | F6: =D6*(1+ASSUMPTIONS!D5) -> 6884724.5 | H6: =F6*(1+ASSUMPTIONS!F5) -> 7469926.1 | J6: =H6*(1+ASSUMPTIONS!H5) -> 8067520.2 | L6: =J6*(1+ASSUMPTIONS!J5) -> 8672584.2 | N6: =L6*(1+ASSUMPTIONS!L5) -> 9279665.1
A7: Cost of Revenue | D7: 3697653 | F7: =F6*ASSUMPTIONS!D7 -> 4061987.4 | H7: =H6*ASSUMPTIONS!F7 -> 4392316.5 | J7: =J6*ASSUMPTIONS!H7 -> 4719499.3 | L7: =L6*ASSUMPTIONS!J7 -> 5047444 | N7: =N6*ASSUMPTIONS!L7 -> 5382205.7
A8: Gross Profit | D8: =D6-D7 -> 2618608 | F8: =F6-F7 -> 2822737 | H8: =H6-H7 -> 3077609.5 | J8: =J6-J7 -> 3348020.9 | L8: =L6-L7 -> 3625140.2 | N8: =N6-N7 -> 3897459.3
A9: Gross Margin | D9: =D8/D6 -> 0.41458198 | E9: =D8/D6 -> 0.41458198 | F9: =F8/F6 -> 0.41 | G9: =F8/F6 -> 0.41 | H9: =H8/H6 -> 0.412 | I9: =H8/H6 -> 0.412 | J9: =J8/J6 -> 0.415 | K9: =J8/J6 -> 0.415 | L9: =L8/L6 -> 0.418 | M9: =L8/L6 -> 0.418 | N9: =N8/N6 -> 0.42 | O9: =N8/N6 -> 0.42
A10: Operating Expense | D10: 2806982 | F10: =F6*ASSUMPTIONS!D9 -> 2444077.2 | H10: =H6*ASSUMPTIONS!F9 -> 2614474.1 | J10: =J6*ASSUMPTIONS!H9 -> 2783294.5 | L10: =L6*ASSUMPTIONS!J9 -> 2948678.6 | N10: =N6*ASSUMPTIONS!L9 -> 3108687.8
A11: EBITDA | D11: 102735 | E11: 102735 | F11: =F8-F10+F15 -> 514977.39 | G11: 203163 | H11: =H8-H10+H15 -> 607304.99 | I11: 203164 | J11: =J8-J10+J15 -> 715589.04 | K11: 203165 | L11: =L8-L10+L15 -> 835169.86 | M11: 203166 | N11: =N8-N10+N15 -> 955805.5 | O11: 203167
A12: EBITDA Margin | D12: =D11/D6 -> 0.016265161 | F12: =F11/F6 -> 0.0748 | H12: =H11/H6 -> 0.0813 | J12: =J11/J6 -> 0.0887 | L12: =L11/L6 -> 0.0963 | N12: =N11/N6 -> 0.103
A13: Operating Income (EBIT) | D13: -188374 | F13: =F11-F15 -> 378659.85 | H13: =H11-H15 -> 463135.42 | J13: =J11-J15 -> 564726.41 | L13: =L11-L15 -> 676461.57 | N13: =N11-N15 -> 788771.53
A14: EBIT Margin | D14: =D13/D6 -> -0.029823657 | F14: =F13/F6 -> 0.055 | H14: =H13/H6 -> 0.062 | J14: =J13/J6 -> 0.07 | L14: =L13/L6 -> 0.078 | N14: =N13/N6 -> 0.085
A15: D&A | D15: 135227 | F15: =F6*ASSUMPTIONS!D11 -> 136317.54 | H15: =H6*ASSUMPTIONS!F11 -> 144169.57 | J15: =J6*ASSUMPTIONS!H11 -> 150862.63 | L15: =L6*ASSUMPTIONS!J11 -> 158708.29 | N15: =N6*ASSUMPTIONS!L11 -> 167033.97
A16: Taxes | D16: -2897255 | F16: =F13*ASSUMPTIONS!D17 -> 56798.977 | H16: =H13*ASSUMPTIONS!F17 -> 78733.021 | J16: =J13*ASSUMPTIONS!H17 -> 107298.02 | L16: =L13*ASSUMPTIONS!J17 -> 142056.93 | N16: =N13*ASSUMPTIONS!L17 -> 173529.74
A17: CapEx | D17: -52822 | F17: =F6*ASSUMPTIONS!D19 -> 68847.245 | H17: =H6*ASSUMPTIONS!F19 -> 82169.187 | J17: =J6*ASSUMPTIONS!H19 -> 96810.242 | L17: =L6*ASSUMPTIONS!J19 -> 112743.59 | N17: =N6*ASSUMPTIONS!L19 -> 139194.98
A18: NWC | D18: ='HISTORICAL FINANCIALS'!D35:E35 -> -1606306 | F18: =F6*ASSUMPTIONS!D21 -> -895014.18 | H18: =H6*ASSUMPTIONS!F21 -> -933740.76 | J18: =J6*ASSUMPTIONS!H21 -> -968102.42 | L18: =L6*ASSUMPTIONS!J21 -> -997347.18 | N18: =N6*ASSUMPTIONS!L21 -> -1020763.2
A22: EBIT | D22: =D13 -> -188374 | F22: =F13 -> 378659.85 | H22: =H13 -> 463135.42 | J22: =J13 -> 564726.41 | L22: =L13 -> 676461.57 | N22: =N13 -> 788771.53
A23: Tax | D23: =D16 -> -2897255 | F23: =F16 -> 56798.977 | H23: =H16 -> 78733.021 | J23: =J16 -> 107298.02 | L23: =L16 -> 142056.93 | N23: =N16 -> 173529.74
A24: NOPAT | D24: =D22-D23 -> 2708881 | F24: =F22-F23 -> 321860.87 | H24: =H22-H23 -> 384402.4 | J24: =J22-J23 -> 457428.39 | L24: =L22-L23 -> 534404.64 | N24: =N22-N23 -> 615241.79
A25: + D&A | D25: =D15 -> 135227 | F25: =F15 -> 136317.54 | H25: =H15 -> 144169.57 | J25: =J15 -> 150862.63 | L25: =L15 -> 158708.29 | N25: =N15 -> 167033.97
A26: - CapEx | D26: =D17 -> -52822 | F26: =F17 -> 68847.245 | H26: =H17 -> 82169.187 | J26: =J17 -> 96810.242 | L26: =L17 -> 112743.59 | N26: =N17 -> 139194.98
A27: - Change in NWC | D27: =D18 -> -1606306 | F27: =F18 -> -895014.18 | H27: =H18 -> -933740.76 | J27: =J18 -> -968102.42 | L27: =L18 -> -997347.18 | N27: =N18 -> -1020763.2
A28: FCF | D28: 1115616 | F28: =F24+F25-F26-F27 -> 1284345.4 | H28: =H24+H25-H26-H27 -> 1380143.5 | J28: =J24+J25-J26-J27 -> 1479583.2 | L28: =L24+L25-L26-L27 -> 1577716.5 | N28: =N24+N25-N26-N27 -> 1663843.9
A29: FCF Margin | D29: =D28/D6 -> 0.17662601 | E29: =D28/D6 -> 0.17662601 | F29: =F28/F6 -> 0.18655 | G29: =F28/F6 -> 0.18655 | H29: =H28/H6 -> 0.18476 | I29: =H28/H6 -> 0.18476 | J29: =J28/J6 -> 0.1834 | K29: =J28/J6 -> 0.1834 | L29: =L28/L6 -> 0.18192 | M29: =L28/L6 -> 0.18192 | N29: =N28/N6 -> 0.1793 | O29: =N28/N6 -> 0.1793

Sheet DCF & SENSITIVITY ANALYSIS
A1: DISCOUNTED CASH FLOW
A4: Dollars in thousands) | L4: Dollars in thousands) | N4: Terminal Value
A5: Terminal Value | D5: =N7 -> 19290833 | G5: Terminal Growth Rate | I5: 0.02 | L5: Perpetural Growth | N5: =(L17*(1+I5))/(I6-I5) -> 24244583
A6: PV of Terminal Value | D6: =D5*L18 -> 12537718 | G6: WACC | I6: 0.09 | L6: EV/EBITDA | N6: =I7*'FORECAST MODEL & FCF BUILD UP'!N11 -> 14337083
A7: Enterprise Value | D7: =SUM(D19:M19)+D6 -> 18219244 | G7: EV/EBITDA Multiple | I7: 15 | L7: Average | N7: =AVERAGE(N5:N6) -> 19290833
A8: Cash | D8: ='HISTORICAL FINANCIALS'!D24:E24 -> 1132009
A9: Debt | D9: ='HISTORICAL FINANCIALS'!D25:E25 -> 0
A10: Equity Value | D10: =D7-D9+D8 -> 19351253
A11: Acquisition Premium | D11: 0.05
A12: Implied Acquisition Value | D12: =(1+D11)*D10 -> 20318815
A15: Dollars in thousands) | D15: FISCAL 2026 | F15: FISCAL 2027 | H15: FISCAL 2028 | J15: FISCAL 2029 | L15: FISCAL 2030 | O15: Terminal Growth → / WACC↓ | R15: =D12 -> 20318815 | S15: 0.015 | T15: 0.02 | U15: 0.025 | V15: 0.025 | W15: 0.035 | X15: 0.04
A16: Year | D16: 1 | F16: 2 | H16: 3 | J16: 4 | L16: 5 | R16: 0.075 | S16: 22941049 | T16: 23932096 | U16: 25121352 | V16: 25121352 | W16: 28391806 | X16: 30727845
A17: FCF | D17: ='FORECAST MODEL & FCF BUILD UP'!F28 -> 1284345.4 | F17: ='FORECAST MODEL & FCF BUILD UP'!H28 -> 1380143.5 | H17: ='FORECAST MODEL & FCF BUILD UP'!J28 -> 1479583.2 | J17: ='FORECAST MODEL & FCF BUILD UP'!L28 -> 1577716.5 | L17: ='FORECAST MODEL & FCF BUILD UP'!N28 -> 1663843.9 | R17: 0.08 | S17: 21725716 | T17: 22548873 | U17: 23521694 | V17: 23521694 | W17: 26115883 | X17: 27899388
A18: Discount Factor | D18: =1/(1+$I$6)^D16 -> 0.91743119 | F18: =1/(1+$I$6)^F16 -> 0.84167999 | H18: =1/(1+$I$6)^H16 -> 0.77218348 | J18: =1/(1+$I$6)^J16 -> 0.70842521 | L18: =1/(1+$I$6)^L16 -> 0.64993139 | R18: 0.085 | S18: 20665279 | T18: 21357925 | U18: 22166013 | V18: 22166013 | W18: 24267040 | X18: 25667725
A19: Present Value | D19: =D17*D18 -> 1178298.5 | F19: =F17*F18 -> 1161639.2 | H19: =H17*H18 -> 1142509.7 | J19: =J17*J18 -> 1117694.2 | L19: =L17*L18 -> 1081384.4 | R19: 0.09 | S19: 19729461 | T19: 20318815 | U19: 20998840 | V19: 20998840 | W19: 22729811 | X19: 23854942
R20: 0.095 | S20: 18895528 | T20: 19401859 | U20: 19980522 | V20: 19980522 | W20: 21427181 | X20: 22347782
R21: 0.1 | S21: 18146071 | T21: 18584765 | U21: 19081953 | V21: 19081953 | W21: 20305798 | X21: 21070701
A23: No of Shares | D23: 400856000
A25: Dollars in thousands) | C25: Intrinsic Value | F25: Market Value vs Intrinsic Value
A26: Enterprise Value | C26: =D7 -> 18219244 | F26: Market Value | I26: =D40 -> 16.534593
A27: ="+ Cash" -> + Cash | C27: =D8 -> 1132009 | F27: Upside | I27: =I28-I26 -> 31.74023
A28: ="- Debt" -> - Debt | C28: =D9 -> 0 | F28: Intrinsic Value | I28: =D31 -> 48.274824
A29: Equity Value | D29: =C26+C27-C28 -> 19351253
A31: Equity Value/Share | D31: =D29/D23*1000 -> 48.274824
A34: Dollars in thousands) | C34: Market Value
A35: Enterprise Value | C35: =7.76*1000000 -> 7760000
A36: ="+ Debt" -> + Debt | C36: 0
A37: ="- Cash" -> - Cash | C37: =D8 -> 1132009
A38: Equity Value | D38: =C35+C36-C37 -> 6627991
A40: Equity Value/Share | D40: =D38/D23*1000 -> 16.534593

Sheet SYNERGIES
A1: Strategic Acquisition Synergies
A4: Dollars in thousands) | L4: Dollars in thousands)
A5: Synergy Type | C5: Description | E5: Financial Impact | G5: Assumption | I5: Annual Savings (USD) | N5: FISCAL 2026 | P5: FISCAL 2027 | R5: FISCAL 2028 | T5: FISCAL 2029 | V5: FISCAL 2030
A6: Administrative efficiencies | C6: Elimination of duplicate departments | E6: Lower SG&A | G6: 10% reduction in overlapping admin functions | I6: =MROUND(0.1*'Income Statement'!L8,100000) -> 200000 | L6: Year | N6: 1 | P6: 2 | R6: 3 | T6: 4 | V6: 5
A7: Reduced competition | C7: Less pricing pressure in ride-sharing market | E7: Higher margins | G7: Reduced duplicate advertising spend | I7: =MROUND(0.17*'Income Statement'!L11,10000) -> 150000 | L7: Synergy Cash Flow | N7: 500000 | P7: 550000 | R7: 575000 | T7: 575000 | V7: 575000
A8: Shared technology platform | C8: Shared AI, routing and infrastructure | E8: Lower R&D expense | G8: Shared platform and infrastructure | I8: 100000 | L8: PV | N8: =(1/(1+ASSUMPTIONS!$D$13)^SYNERGIES!N6)*N7 -> 458715.6 | P8: =(1/(1+ASSUMPTIONS!$D$13)^SYNERGIES!P6)*P7 -> 462924 | R8: =(1/(1+ASSUMPTIONS!$D$13)^SYNERGIES!R6)*R7 -> 444005.5 | T8: =(1/(1+ASSUMPTIONS!$D$13)^SYNERGIES!T6)*T7 -> 407344.5 | V8: =(1/(1+ASSUMPTIONS!$D$13)^SYNERGIES!V6)*V7 -> 373710.55 | X8: =SUM(N8:W8) -> 2146700.1
A9: Driver network optimization | C9: Combined driver pool improves efficiency and reduces idle time | E9: Lower operating costs | G9: Better driver allocation and utilization | I9: 75000
A10: Combined market share | C10: Larger customer base across regions | E10: Revenue growth | G10: Vendor and operational savings | I10: 50000
A11: Total Annual Synergies | J11: =SUM(I6:J10) -> 575000
A14: Dollars in thousands) | C14: Intrinsic Value
A15: Standalone Lyft EV | C15: ='DCF & SENSITIVITY ANALYSIS'!D7 -> 18219244
A16: PV of Synergies | C16: =X8 -> 2146700.1 | D16: =X8 -> 2146700.1
A17: Strategic acquision value | C17: =C15+C16 -> 20365944 | D17: =C15+D16 -> 20365944

Sheet RECOMMENDATION
A1: Recommendation
A3: Final Recommendation
A5: Based on the DCF valuation, projected synergies, and long term strategic benefits, the acquisition appears to provide strong strategic value for Uber. The transaction could strengthen Uber’s market leadership, improve operational efficiencies, and enhance long term profitability. However, the success of the acquisition would heavily depend on, 1. obtaining regulatory approval 2. successful integration of operations 3. effective realization of projected synergies While the transaction presents measningful risks, particularly related to antitrust concerns and execcution challenges, the overall startegic and financial benefits may outweigh the potential drawbacks if managed effectively, Therefore, the acquisition may be considered strategically favorable, subjected to desciplined valuation and successful execution of post merger integration initatives.
